[2023-07-05T13:29:44.540+0000] {taskinstance.py:1103} INFO - Dependencies all met for dep_context=non-requeueable deps ti=<TaskInstance: exercise17.drop_table manual__2023-07-05T13:29:42.160988+00:00 [queued]>
[2023-07-05T13:29:44.572+0000] {taskinstance.py:1103} INFO - Dependencies all met for dep_context=requeueable deps ti=<TaskInstance: exercise17.drop_table manual__2023-07-05T13:29:42.160988+00:00 [queued]>
[2023-07-05T13:29:44.572+0000] {taskinstance.py:1308} INFO - Starting attempt 1 of 1
[2023-07-05T13:29:44.606+0000] {taskinstance.py:1327} INFO - Executing <Task(SqliteOperator): drop_table> on 2023-07-05 13:29:42.160988+00:00
[2023-07-05T13:29:44.618+0000] {standard_task_runner.py:57} INFO - Started process 201 to run task
[2023-07-05T13:29:44.622+0000] {standard_task_runner.py:84} INFO - Running: ['***', 'tasks', 'run', 'exercise17', 'drop_table', 'manual__2023-07-05T13:29:42.160988+00:00', '--job-id', '9', '--raw', '--subdir', 'DAGS_FOLDER/sqlexercise.py', '--cfg-path', '/tmp/tmp84ofophu']
[2023-07-05T13:29:44.623+0000] {standard_task_runner.py:85} INFO - Job 9: Subtask drop_table
[2023-07-05T13:29:44.712+0000] {task_command.py:410} INFO - Running <TaskInstance: exercise17.drop_table manual__2023-07-05T13:29:42.160988+00:00 [running]> on host da250f106141
[2023-07-05T13:29:44.845+0000] {taskinstance.py:1547} INFO - Exporting env vars: AIRFLOW_CTX_DAG_OWNER='***' AIRFLOW_CTX_DAG_ID='exercise17' AIRFLOW_CTX_TASK_ID='drop_table' AIRFLOW_CTX_EXECUTION_DATE='2023-07-05T13:29:42.160988+00:00' AIRFLOW_CTX_TRY_NUMBER='1' AIRFLOW_CTX_DAG_RUN_ID='manual__2023-07-05T13:29:42.160988+00:00'
[2023-07-05T13:29:44.846+0000] {sql.py:265} INFO - Executing: DROP TABLE cities;
[2023-07-05T13:29:44.872+0000] {taskinstance.py:1824} ERROR - Task failed with exception
Traceback (most recent call last):
  File "/home/airflow/.local/lib/python3.7/site-packages/airflow/providers/common/sql/operators/sql.py", line 266, in execute
    hook = self.get_db_hook()
  File "/home/airflow/.local/lib/python3.7/site-packages/airflow/providers/common/sql/operators/sql.py", line 181, in get_db_hook
    return self._hook
  File "/home/airflow/.local/lib/python3.7/site-packages/cached_property.py", line 36, in __get__
    value = obj.__dict__[self.func.__name__] = self.func(obj)
  File "/home/airflow/.local/lib/python3.7/site-packages/airflow/providers/common/sql/operators/sql.py", line 143, in _hook
    conn = BaseHook.get_connection(self.conn_id)
  File "/home/airflow/.local/lib/python3.7/site-packages/airflow/hooks/base.py", line 72, in get_connection
    conn = Connection.get_connection_from_secrets(conn_id)
  File "/home/airflow/.local/lib/python3.7/site-packages/airflow/models/connection.py", line 434, in get_connection_from_secrets
    raise AirflowNotFoundException(f"The conn_id `{conn_id}` isn't defined")
airflow.exceptions.AirflowNotFoundException: The conn_id `sqlite_test` isn't defined
[2023-07-05T13:29:44.880+0000] {taskinstance.py:1350} INFO - Marking task as FAILED. dag_id=exercise17, task_id=drop_table, execution_date=20230705T132942, start_date=20230705T132944, end_date=20230705T132944
[2023-07-05T13:29:44.898+0000] {standard_task_runner.py:109} ERROR - Failed to execute job 9 for task drop_table (The conn_id `sqlite_test` isn't defined; 201)
[2023-07-05T13:29:44.919+0000] {local_task_job_runner.py:225} INFO - Task exited with return code 1
[2023-07-05T13:29:44.956+0000] {taskinstance.py:2653} INFO - 0 downstream tasks scheduled from follow-on schedule check
